Workbook

Sheet Annotated by thesis author
A1: Paper number | B1: Paper Title | C1: Author | D1: Link to Paper | E1: Year | F1: Data availability | G1: Inclusion of a ReadMe | H1: Trained model inclusion | I1: Hyperparameter description | J1: Training description | K1: Paper readability | L1: Code availability | M1: The reproducibility factor from the dataset by Olszewski et al.
A2: 704 | B2: DataLens: Scalable Privacy Preserving Training via Gradient Compression and Aggregation | C2: Boxin Wang, Fan Wu, Yunhui Long, Luka Rimanic, Ce Zhang, Bo Li | D2: https://dl.acm.org/doi/pdf/10.1145/3460120.3484579 | E2: 2021 | F2: 3 | G2: 2 | H2: 0 | I2: 2 | J2: 2 | K2: 2 | L2: 2 | M2: 1
A3: 735 | B3: CRYPTGPU: Fast Privacy-Preserving Machine Learning on the GPU | C3: Sijun Tan, Brian Knott, Yuan Tian, David J. Wu | D3: https://ieeexplore.ieee.org/stamp/stamp.jsp?tp=&arnumber=9519386 | E3: 2021 | F3: 3 | G3: 1 | H3: 0 | I3: 1 | J3: 1 | K3: 2 | L3: 2 | M3: 0
A4: 546 | B4: SkillDetective: Automated Policy-Violation Detection of Voice Assistant Applications in the Wild | C4: Jeffrey Young, Song Liao, and Long Cheng, Hongxin Hu, Huixing Deng | D4: https://www.usenix.org/system/files/sec22-young.pdf | E4: 2022 | F4: 3 | G4: 2 | H4: 0 | I4: 1 | J4: 1 | K4: 1 | L4: 2 | M4: 0
A5: 634 | B5: Cost-Aware Robust Tree Ensembles for Security Applications | C5: Yizheng Chen, Shiqi Wang, Weifan Jiang, Asaf Cidon, and Suman Jana | D5: https://www.usenix.org/system/files/sec21-chen-yizheng.pdf | E5: 2021 | F5: 3 | G5: 1 | H5: 0 | I5: 2 | J5: 2 | K5: 2 | L5: 2 | M5: 1
A6: 69 | B6: Latent Backdoor Attacks on Deep Neural Networks | C6: Yuanshun Yao, Huiying Li, Haitao Zheng, Ben Y. Zhao | D6: https://dl.acm.org/doi/pdf/10.1145/3319535.3354209 | E6: 2019 | F6: 2 | G6: 0 | H6: 0 | I6: 2 | J6: 1 | K6: 2 | L6: 0 | M6: 1
A7: 454 | B7: Auditing Membership Leakages of Multi-Exit Networks | C7: Zheng Li, Yiyong Liu, Xinlei He, Ning Yu, Michael Backes, Yang Zhang | D7: https://doi.org/10.1145/3548606.3559359 | E7: 2022 | F7: 3 | G7: 0 | H7: 0 | I7: 1 | J7: 1 | K7: 2 | L7: 0 | M7: 0
A8: 610 | B8: DeepReflect: Discovering Malicious Functionality through Binary Reconstruction | C8: Evan Downing, Yisroel Mirsky, Kyuhong Park, Wenke Lee | D8: https://www.usenix.org/conference/usenixsecurity21/presentation/downing | E8: 2021 | F8: 2 | G8: 2 | H8: 0 | I8: 2 | J8: 2 | K8: 2 | L8: 2 | M8: 0
A9: 302 | B9: Effective Attacks and Provable Defenses for Website Fingerprinting | C9: Tao Wang; Xiang Cai; Rishab Nithyanand; Rob Johnson; Ian Goldberg | D9: https://www.usenix.org/system/files/conference/usenixsecurity14/sec14-paper-wang-tao.pdf | E9: 2014 | F9: 2 | G9: 2 | H9: 0 | I9: 2 | J9: 2 | K9: 2 | L9: 2 | M9: 0
A10: 714 | B10: DetectorGuard: Provably Securing Object Detectors against Localized Patch Hiding Attacks | C10: Chong Xiang, Prateek Mittal | D10: https://dl.acm.org/doi/pdf/10.1145/3460120.3484757 | E10: 2021 | F10: 3 | G10: 2 | H10: 0 | I10: 2 | J10: 2 | K10: 2 | L10: 2 | M10: 1
A11: 547 | B11: Hand Me Your PIN! Inferring ATM PINs of Users Typing with a Covered Hand | C11: Matteo Cardaioli, Stefano Cecconello, Mauro Conti, Simone Milani, Stjepan Picek, Eugen Saraci | D11: https://www.usenix.org/system/files/sec22-cardaioli.pdf | E11: 2022 | F11: 2 | G11: 0 | H11: 0 | I11: 1 | J11: 1 | K11: 2 | L11: 0 | M11: 0
A12: 592 | B12: What You See is Not What the Network Infers: Detecting Adversarial Examples Based on Semantic Contradiction | C12: Yijun Yang, Ruiyuan Gao, Yu Li, Qiuxia Lai, Qiang Xu | D12: https://www.ndss-symposium.org/wp-content/uploads/2022-1-paper.pdf | E12: 2022 | F12: 2 | G12: 2 | H12: 1 | I12: 2 | J12: 2 | K12: 2 | L12: 2 | M12: 0
A13: 108 | B13: GAN-Leaks: A Taxonomy of Membership Inference Attacks against Generative Models | C13: Dingfan Chen; Ning Yu; Yang Zhang ; Mario Fritz | D13: https://dl.acm.org/doi/pdf/10.1145/3372297.3417238 | E13: 2020 | F13: 3 | G13: 1 | H13: 0 | I13: 2 | J13: 2 | K13: 2 | L13: 2 | M13: 0
... A140: 320 | B140: Effective Detection of Multimedia Protocol Tunneling using Machine Learning | C140: Diogo Barradas, Nuno Santos, and LuÃ­s Rodrigues | D140: https://www.usenix.org/system/files/conference/usenixsecurity18/sec18-barradas.pdf | E140: 2018 | F140: 0 | G140: 0 | H140: 0 | I140: 0 | J140: 0 | K140: 1 | L140: 0 | M140: 0

Sheet Annotated by ChatGPT
A1: Paper number | B1: Paper Title | C1: Author | D1: Link to Paper | E1: Year | F1: Data availability | G1: Inclusion of a ReadMe | H1: Trained model inclusion | I1: Hyperparameter description | J1: Training description | K1: Paper readability | L1: Code availability | M1: The reproducibility factor from the dataset by Olszewski et al.
A2: 704 | B2: DataLens: Scalable Privacy Preserving Training via Gradient Compression and Aggregation | C2: Boxin Wang, Fan Wu, Yunhui Long, Luka Rimanic, Ce Zhang, Bo Li | D2: https://dl.acm.org/doi/pdf/10.1145/3460120.3484579 | E2: 2021 | F2: 3 | G2: 2 | H2: 0 | I2: 2 | J2: 2 | K2: 2 | L2: 2 | M2: 1
A3: 735 | B3: CRYPTGPU: Fast Privacy-Preserving Machine Learning on the GPU | C3: Sijun Tan, Brian Knott, Yuan Tian, David J. Wu | D3: https://ieeexplore.ieee.org/stamp/stamp.jsp?tp=&arnumber=9519386 | E3: 2021 | F3: 3 | G3: 1 | H3: 0 | I3: 2 | J3: 1 | K3: 2 | L3: 2 | M3: 0
A4: 546 | B4: SkillDetective: Automated Policy-Violation Detection of Voice Assistant Applications in the Wild | C4: Jeffrey Young, Song Liao, and Long Cheng, Hongxin Hu, Huixing Deng | D4: https://www.usenix.org/system/files/sec22-young.pdf | E4: 2022 | F4: 3 | G4: 2 | H4: 0 | I4: 1 | J4: 1 | K4: 1 | L4: 2 | M4: 0
A5: 634 | B5: Cost-Aware Robust Tree Ensembles for Security Applications | C5: Yizheng Chen, Shiqi Wang, Weifan Jiang, Asaf Cidon, and Suman Jana | D5: https://www.usenix.org/system/files/sec21-chen-yizheng.pdf | E5: 2021 | F5: 2 | G5: 1 | H5: 0 | I5: 2 | J5: 2 | K5: 2 | L5: 2 | M5: 1
A6: 69 | B6: Latent Backdoor Attacks on Deep Neural Networks | C6: Yuanshun Yao, Huiying Li, Haitao Zheng, Ben Y. Zhao | D6: https://dl.acm.org/doi/pdf/10.1145/3319535.3354209 | E6: 2019 | F6: 2 | G6: 0 | H6: 0 | I6: 2 | J6: 2 | K6: 2 | L6: 0 | M6: 1
A7: 454 | B7: Auditing Membership Leakages of Multi-Exit Networks | C7: Zheng Li, Yiyong Liu, Xinlei He, Ning Yu, Michael Backes, Yang Zhang | D7: https://doi.org/10.1145/3548606.3559359 | E7: 2022 | F7: 2 | G7: 0 | H7: 0 | I7: 2 | J7: 2 | K7: 2 | L7: 0 | M7: 0
A8: 610 | B8: DeepReflect: Discovering Malicious Functionality through Binary Reconstruction | C8: Evan Downing, Yisroel Mirsky, Kyuhong Park, Wenke Lee | D8: https://www.usenix.org/conference/usenixsecurity21/presentation/downing | E8: 2021 | F8: 2 | G8: 2 | H8: 0 | I8: 2 | J8: 2 | K8: 2 | L8: 2 | M8: 0
A9: 302 | B9: Effective Attacks and Provable Defenses for Website Fingerprinting | C9: Tao Wang; Xiang Cai; Rishab Nithyanand; Rob Johnson; Ian Goldberg | D9: https://www.usenix.org/system/files/conference/usenixsecurity14/sec14-paper-wang-tao.pdf | E9: 2014 | F9: 2 | G9: 2 | H9: 0 | I9: 2 | J9: 2 | K9: 2 | L9: 2 | M9: 0
A10: 714 | B10: DetectorGuard: Provably Securing Object Detectors against Localized Patch Hiding Attacks | C10: Chong Xiang, Prateek Mittal | D10: https://dl.acm.org/doi/pdf/10.1145/3460120.3484757 | E10: 2021 | F10: 3 | G10: 2 | H10: 0 | I10: 2 | J10: 2 | K10: 2 | L10: 2 | M10: 1
A11: 547 | B11: Hand Me Your PIN! Inferring ATM PINs of Users Typing with a Covered Hand | C11: Matteo Cardaioli, Stefano Cecconello, Mauro Conti, Simone Milani, Stjepan Picek, Eugen Saraci | D11: https://www.usenix.org/system/files/sec22-cardaioli.pdf | E11: 2022 | F11: 2 | G11: 0 | H11: 0 | I11: 1 | J11: 1 | K11: 2 | L11: 0 | M11: 0
A12: 592 | B12: What You See is Not What the Network Infers: Detecting Adversarial Examples Based on Semantic Contradiction | C12: Yijun Yang, Ruiyuan Gao, Yu Li, Qiuxia Lai, Qiang Xu | D12: https://www.ndss-symposium.org/wp-content/uploads/2022-1-paper.pdf | E12: 2022 | F12: 2 | G12: 2 | H12: 1 | I12: 2 | J12: 2 | K12: 2 | L12: 2 | M12: 0
A13: 108 | B13: GAN-Leaks: A Taxonomy of Membership Inference Attacks against Generative Models | C13: Dingfan Chen; Ning Yu; Yang Zhang ; Mario Fritz | D13: https://dl.acm.org/doi/pdf/10.1145/3372297.3417238 | E13: 2020 | F13: 3 | G13: 1 | H13: 0 | I13: 2 | J13: 2 | K13: 2 | L13: 2 | M13: 0
... A140: 320 | B140: Effective Detection of Multimedia Protocol Tunneling using Machine Learning | C140: Diogo Barradas, Nuno Santos, and LuÃ­s Rodrigues | D140: https://www.usenix.org/system/files/conference/usenixsecurity18/sec18-barradas.pdf | E140: 2018 | F140: 0 | G140: 0 | H140: 0 | I140: 0 | J140: 0 | K140: 2 | L140: 0 | M140: 0

Sheet Final Annotation
A1: Paper number | B1: Paper Title | C1: Author | D1: Link to Paper | E1: Year | F1: Data availability | G1: Inclusion of a ReadMe | H1: Trained model inclusion | I1: Hyperparameter description | J1: Training description | K1: Paper readability | L1: Code availability | M1: The reproducibility factor from the dataset by Olszewski et al.
A2: 704 | B2: DataLens: Scalable Privacy Preserving Training via Gradient Compression and Aggregation | C2: Boxin Wang, Fan Wu, Yunhui Long, Luka Rimanic, Ce Zhang, Bo Li | D2: https://dl.acm.org/doi/pdf/10.1145/3460120.3484579 | E2: 2021 | F2: =('Annotated by thesis author'!F2+'Annotated by ChatGPT'!F2)/2 -> 3 | G2: =('Annotated by thesis author'!G2+'Annotated by ChatGPT'!G2)/2 -> 2 | H2: =('Annotated by thesis author'!H2+'Annotated by ChatGPT'!H2)/2 -> 0 | I2: =('Annotated by thesis author'!I2+'Annotated by ChatGPT'!I2)/2 -> 2 | J2: =('Annotated by thesis author'!J2+'Annotated by ChatGPT'!J2)/2 -> 2 | K2: =('Annotated by thesis author'!K2+'Annotated by ChatGPT'!K2)/2 -> 2 | L2: =('Annotated by thesis author'!L2+'Annotated by ChatGPT'!L2)/2 -> 2 | M2: 1
A3: 735 | B3: CRYPTGPU: Fast Privacy-Preserving Machine Learning on the GPU | C3: Sijun Tan, Brian Knott, Yuan Tian, David J. Wu | D3: https://ieeexplore.ieee.org/stamp/stamp.jsp?tp=&arnumber=9519386 | E3: 2021 | F3: =('Annotated by thesis author'!F3+'Annotated by ChatGPT'!F3)/2 -> 3 | G3: =('Annotated by thesis author'!G3+'Annotated by ChatGPT'!G3)/2 -> 1 | H3: =('Annotated by thesis author'!H3+'Annotated by ChatGPT'!H3)/2 -> 0 | I3: 1 | J3: =('Annotated by thesis author'!J3+'Annotated by ChatGPT'!J3)/2 -> 1 | K3: =('Annotated by thesis author'!K3+'Annotated by ChatGPT'!K3)/2 -> 2 | L3: =('Annotated by thesis author'!L3+'Annotated by ChatGPT'!L3)/2 -> 2 | M3: 0
A4: 546 | B4: SkillDetective: Automated Policy-Violation Detection of Voice Assistant Applications in the Wild | C4: Jeffrey Young, Song Liao, and Long Cheng, Hongxin Hu, Huixing Deng | D4: https://www.usenix.org/system/files/sec22-young.pdf | E4: 2022 | F4: =('Annotated by thesis author'!F4+'Annotated by ChatGPT'!F4)/2 -> 3 | G4: =('Annotated by thesis author'!G4+'Annotated by ChatGPT'!G4)/2 -> 2 | H4: =('Annotated by thesis author'!H4+'Annotated by ChatGPT'!H4)/2 -> 0 | I4: =('Annotated by thesis author'!I4+'Annotated by ChatGPT'!I4)/2 -> 1 | J4: =('Annotated by thesis author'!J4+'Annotated by ChatGPT'!J4)/2 -> 1 | K4: =('Annotated by thesis author'!K4+'Annotated by ChatGPT'!K4)/2 -> 1 | L4: =('Annotated by thesis author'!L4+'Annotated by ChatGPT'!L4)/2 -> 2 | M4: 0
A5: 634 | B5: Cost-Aware Robust Tree Ensembles for Security Applications | C5: Yizheng Chen, Shiqi Wang, Weifan Jiang, Asaf Cidon, and Suman Jana | D5: https://www.usenix.org/system/files/sec21-chen-yizheng.pdf | E5: 2021 | F5: 2 | G5: =('Annotated by thesis author'!G5+'Annotated by ChatGPT'!G5)/2 -> 1 | H5: =('Annotated by thesis author'!H5+'Annotated by ChatGPT'!H5)/2 -> 0 | I5: =('Annotated by thesis author'!I5+'Annotated by ChatGPT'!I5)/2 -> 2 | J5: =('Annotated by thesis author'!J5+'Annotated by ChatGPT'!J5)/2 -> 2 | K5: =('Annotated by thesis author'!K5+'Annotated by ChatGPT'!K5)/2 -> 2 | L5: =('Annotated by thesis author'!L5+'Annotated by ChatGPT'!L5)/2 -> 2 | M5: 1
A6: 69 | B6: Latent Backdoor Attacks on Deep Neural Networks | C6: Yuanshun Yao, Huiying Li, Haitao Zheng, Ben Y. Zhao | D6: https://dl.acm.org/doi/pdf/10.1145/3319535.3354209 | E6: 2019 | F6: =('Annotated by thesis author'!F6+'Annotated by ChatGPT'!F6)/2 -> 2 | G6: =('Annotated by thesis author'!G6+'Annotated by ChatGPT'!G6)/2 -> 0 | H6: =('Annotated by thesis author'!H6+'Annotated by ChatGPT'!H6)/2 -> 0 | I6: =('Annotated by thesis author'!I6+'Annotated by ChatGPT'!I6)/2 -> 2 | J6: 1 | K6: =('Annotated by thesis author'!K6+'Annotated by ChatGPT'!K6)/2 -> 2 | L6: =('Annotated by thesis author'!L6+'Annotated by ChatGPT'!L6)/2 -> 0 | M6: 1
A7: 454 | B7: Auditing Membership Leakages of Multi-Exit Networks | C7: Zheng Li, Yiyong Liu, Xinlei He, Ning Yu, Michael Backes, Yang Zhang | D7: https://doi.org/10.1145/3548606.3559359 | E7: 2022 | F7: 2 | G7: =('Annotated by thesis author'!G7+'Annotated by ChatGPT'!G7)/2 -> 0 | H7: =('Annotated by thesis author'!H7+'Annotated by ChatGPT'!H7)/2 -> 0 | I7: 1 | J7: 1 | K7: =('Annotated by thesis author'!K7+'Annotated by ChatGPT'!K7)/2 -> 2 | L7: =('Annotated by thesis author'!L7+'Annotated by ChatGPT'!L7)/2 -> 0 | M7: 0
A8: 610 | B8: DeepReflect: Discovering Malicious Functionality through Binary Reconstruction | C8: Evan Downing, Yisroel Mirsky, Kyuhong Park, Wenke Lee | D8: https://www.usenix.org/conference/usenixsecurity21/presentation/downing | E8: 2021 | F8: =('Annotated by thesis author'!F8+'Annotated by ChatGPT'!F8)/2 -> 2 | G8: =('Annotated by thesis author'!G8+'Annotated by ChatGPT'!G8)/2 -> 2 | H8: =('Annotated by thesis author'!H8+'Annotated by ChatGPT'!H8)/2 -> 0 | I8: =('Annotated by thesis author'!I8+'Annotated by ChatGPT'!I8)/2 -> 2 | J8: =('Annotated by thesis author'!J8+'Annotated by ChatGPT'!J8)/2 -> 2 | K8: =('Annotated by thesis author'!K8+'Annotated by ChatGPT'!K8)/2 -> 2 | L8: =('Annotated by thesis author'!L8+'Annotated by ChatGPT'!L8)/2 -> 2 | M8: 0
A9: 302 | B9: Effective Attacks and Provable Defenses for Website Fingerprinting | C9: Tao Wang; Xiang Cai; Rishab Nithyanand; Rob Johnson; Ian Goldberg | D9: https://www.usenix.org/system/files/conference/usenixsecurity14/sec14-paper-wang-tao.pdf | E9: 2014 | F9: =('Annotated by thesis author'!F9+'Annotated by ChatGPT'!F9)/2 -> 2 | G9: =('Annotated by thesis author'!G9+'Annotated by ChatGPT'!G9)/2 -> 2 | H9: =('Annotated by thesis author'!H9+'Annotated by ChatGPT'!H9)/2 -> 0 | I9: =('Annotated by thesis author'!I9+'Annotated by ChatGPT'!I9)/2 -> 2 | J9: =('Annotated by thesis author'!J9+'Annotated by ChatGPT'!J9)/2 -> 2 | K9: =('Annotated by thesis author'!K9+'Annotated by ChatGPT'!K9)/2 -> 2 | L9: =('Annotated by thesis author'!L9+'Annotated by ChatGPT'!L9)/2 -> 2 | M9: 0
A10: 714 | B10: DetectorGuard: Provably Securing Object Detectors against Localized Patch Hiding Attacks | C10: Chong Xiang, Prateek Mittal | D10: https://dl.acm.org/doi/pdf/10.1145/3460120.3484757 | E10: 2021 | F10: =('Annotated by thesis author'!F10+'Annotated by ChatGPT'!F10)/2 -> 3 | G10: =('Annotated by thesis author'!G10+'Annotated by ChatGPT'!G10)/2 -> 2 | H10: =('Annotated by thesis author'!H10+'Annotated by ChatGPT'!H10)/2 -> 0 | I10: =('Annotated by thesis author'!I10+'Annotated by ChatGPT'!I10)/2 -> 2 | J10: =('Annotated by thesis author'!J10+'Annotated by ChatGPT'!J10)/2 -> 2 | K10: =('Annotated by thesis author'!K10+'Annotated by ChatGPT'!K10)/2 -> 2 | L10: =('Annotated by thesis author'!L10+'Annotated by ChatGPT'!L10)/2 -> 2 | M10: 1
A11: 547 | B11: Hand Me Your PIN! Inferring ATM PINs of Users Typing with a Covered Hand | C11: Matteo Cardaioli, Stefano Cecconello, Mauro Conti, Simone Milani, Stjepan Picek, Eugen Saraci | D11: https://www.usenix.org/system/files/sec22-cardaioli.pdf | E11: 2022 | F11: =('Annotated by thesis author'!F11+'Annotated by ChatGPT'!F11)/2 -> 2 | G11: =('Annotated by thesis author'!G11+'Annotated by ChatGPT'!G11)/2 -> 0 | H11: =('Annotated by thesis author'!H11+'Annotated by ChatGPT'!H11)/2 -> 0 | I11: =('Annotated by thesis author'!I11+'Annotated by ChatGPT'!I11)/2 -> 1 | J11: =('Annotated by thesis author'!J11+'Annotated by ChatGPT'!J11)/2 -> 1 | K11: =('Annotated by thesis author'!K11+'Annotated by ChatGPT'!K11)/2 -> 2 | L11: =('Annotated by thesis author'!L11+'Annotated by ChatGPT'!L11)/2 -> 0 | M11: 0
A12: 592 | B12: What You See is Not What the Network Infers: Detecting Adversarial Examples Based on Semantic Contradiction | C12: Yijun Yang, Ruiyuan Gao, Yu Li, Qiuxia Lai, Qiang Xu | D12: https://www.ndss-symposium.org/wp-content/uploads/2022-1-paper.pdf | E12: 2022 | F12: =('Annotated by thesis author'!F12+'Annotated by ChatGPT'!F12)/2 -> 2 | G12: =('Annotated by thesis author'!G12+'Annotated by ChatGPT'!G12)/2 -> 2 | H12: =('Annotated by thesis author'!H12+'Annotated by ChatGPT'!H12)/2 -> 1 | I12: =('Annotated by thesis author'!I12+'Annotated by ChatGPT'!I12)/2 -> 2 | J12: =('Annotated by thesis author'!J12+'Annotated by ChatGPT'!J12)/2 -> 2 | K12: =('Annotated by thesis author'!K12+'Annotated by ChatGPT'!K12)/2 -> 2 | L12: =('Annotated by thesis author'!L12+'Annotated by ChatGPT'!L12)/2 -> 2 | M12: 0
A13: 108 | B13: GAN-Leaks: A Taxonomy of Membership Inference Attacks against Generative Models | C13: Dingfan Chen; Ning Yu; Yang Zhang ; Mario Fritz | D13: https://dl.acm.org/doi/pdf/10.1145/3372297.3417238 | E13: 2020 | F13: =('Annotated by thesis author'!F13+'Annotated by ChatGPT'!F13)/2 -> 3 | G13: =('Annotated by thesis author'!G13+'Annotated by ChatGPT'!G13)/2 -> 1 | H13: =('Annotated by thesis author'!H13+'Annotated by ChatGPT'!H13)/2 -> 0 | I13: =('Annotated by thesis author'!I13+'Annotated by ChatGPT'!I13)/2 -> 2 | J13: =('Annotated by thesis author'!J13+'Annotated by ChatGPT'!J13)/2 -> 2 | K13: =('Annotated by thesis author'!K13+'Annotated by ChatGPT'!K13)/2 -> 2 | L13: =('Annotated by thesis author'!L13+'Annotated by ChatGPT'!L13)/2 -> 2 | M13: 0
A14: 664 | B14: Evading Voltage-Based Intrusion Detection on Automotive CAN | C14: Rohit Bhatia, Vireshwar Kumar, Khaled Serag, Z. Berkay Celik, Mathias Payer and Dongyan Xu | D14: https://www.ndss-symposium.org/wp-content/uploads/ndss2021_6B-1_23013_paper.pdf | E14: 2021 | F14: =('Annotated by thesis author'!F14+'Annotated by ChatGPT'!F14)/2 -> 0 | G14: =('Annotated by thesis author'!G14+'Annotated by ChatGPT'!G14)/2 -> 0 | H14: =('Annotated by thesis author'!H14+'Annotated by ChatGPT'!H14)/2 -> 0 | I14: =('Annotated by thesis author'!I14+'Annotated by ChatGPT'!I14)/2 -> 1 | J14: =('Annotated by thesis author'!J14+'Annotated by ChatGPT'!J14)/2 -> 1 | K14: =('Annotated by thesis author'!K14+'Annotated by ChatGPT'!K14)/2 -> 1 | L14: =('Annotated by thesis author'!L14+'Annotated by ChatGPT'!L14)/2 -> 0 | M14: 0
A15: 44 | B15: Exploiting Unintended Feature Leakage in Collaborative Learning | C15: Luca Melis, Congzheng Song, Emiliano De Cristofaro, Vitaly Shmatikov | D15: https://ieeexplore.ieee.org/stamp/stamp.jsp?arnumber=8835269 | E15: 2019 | F15: =('Annotated by thesis author'!F15+'Annotated by ChatGPT'!F15)/2 -> 2 | G15: =('Annotated by thesis author'!G15+'Annotated by ChatGPT'!G15)/2 -> 0 | H15: =('Annotated by thesis author'!H15+'Annotated by ChatGPT'!H15)/2 -> 0 | I15: =('Annotated by thesis author'!I15+'Annotated by ChatGPT'!I15)/2 -> 1 | J15: =('Annotated by thesis author'!J15+'Annotated by ChatGPT'!J15)/2 -> 1 | K15: =('Annotated by thesis author'!K15+'Annotated by ChatGPT'!K15)/2 -> 2 | L15: =('Annotated by thesis author'!L15+'Annotated by ChatGPT'!L15)/2 -> 0 | M15: 0
A16: 269 | B16: Model Stealing Attacks Against Inductive Graph Neural Networks | C16: Yun Shen, Xinlei He, Yufei Han, Yang Zhang | D16: https://ieeexplore.ieee.org/stamp/stamp.jsp?arnumber=9833607 | E16: 2022 | F16: =('Annotated by thesis author'!F16+'Annotated by ChatGPT'!F16)/2 -> 2 | G16: =('Annotated by thesis author'!G16+'Annotated by ChatGPT'!G16)/2 -> 0 | H16: =('Annotated by thesis author'!H16+'Annotated by ChatGPT'!H16)/2 -> 0 | I16: =('Annotated by thesis author'!I16+'Annotated by ChatGPT'!I16)/2 -> 2 | J16: =('Annotated by thesis author'!J16+'Annotated by ChatGPT'!J16)/2 -> 2 | K16: 1 | L16: =('Annotated by thesis author'!L16+'Annotated by ChatGPT'!L16)/2 -> 0 | M16: 1
A17: 629 | B17: GForce: GPU-Friendly Oblivious and Rapid Neural Network Inference | C17: Lucien K. L. Ng and Sherman S. M. Chow | D17: https://www.usenix.org/system/files/sec21-ng.pdf | E17: 2021 | F17: =('Annotated by thesis author'!F17+'Annotated by ChatGPT'!F17)/2 -> 2 | G17: =('Annotated by thesis author'!G17+'Annotated by ChatGPT'!G17)/2 -> 0 | H17: =('Annotated by thesis author'!H17+'Annotated by ChatGPT'!H17)/2 -> 0 | I17: =('Annotated by thesis author'!I17+'Annotated by ChatGPT'!I17)/2 -> 2 | J17: =('Annotated by thesis author'!J17+'Annotated by ChatGPT'!J17)/2 -> 2 | K17: =('Annotated by thesis author'!K17+'Annotated by ChatGPT'!K17)/2 -> 2 | L17: =('Annotated by thesis author'!L17+'Annotated by ChatGPT'!L17)/2 -> 0 | M17: 1
A18: 620 | B18: SmarTest: Effectively Hunting Vulnerable Transaction Sequences in Smart Contracts through Language Model-Guided Symbolic Execution | C18: Sunbeom So, Seongjoon Hong, Hakjoo Oh | D18: https://www.usenix.org/system/files/sec21-so.pdf | E18: 2021 | F18: =('Annotated by thesis author'!F18+'Annotated by ChatGPT'!F18)/2 -> 0 | G18: =('Annotated by thesis author'!G18+'Annotated by ChatGPT'!G18)/2 -> 0 | H18: =('Annotated by thesis author'!H18+'Annotated by ChatGPT'!H18)/2 -> 0 | I18: =('Annotated by thesis author'!I18+'Annotated by ChatGPT'!I18)/2 -> 0 | J18: =('Annotated by thesis author'!J18+'Annotated by ChatGPT'!J18)/2 -> 1 | K18: =('Annotated by thesis author'!K18+'Annotated by ChatGPT'!K18)/2 -> 0 | L18: =('Annotated by thesis author'!L18+'Annotated by ChatGPT'!L18)/2 -> 1 | M18: 0
A19: 78 | B19: Neural Network Inversion in Adversarial Setting via_x000D_ Background Knowledge Alignment | C19: Ziqi Yang, Jiyi Zhang, Ee-Chien Chang, Zhenkai Liang | D19: https://dl.acm.org/doi/pdf/10.1145/3319535.3354261 | E19: 2019 | F19: =('Annotated by thesis author'!F19+'Annotated by ChatGPT'!F19)/2 -> 2 | G19: =('Annotated by thesis author'!G19+'Annotated by ChatGPT'!G19)/2 -> 0 | H19: =('Annotated by thesis author'!H19+'Annotated by ChatGPT'!H19)/2 -> 0 | I19: =('Annotated by thesis author'!I19+'Annotated by ChatGPT'!I19)/2 -> 1 | J19: =('Annotated by thesis author'!J19+'Annotated by ChatGPT'!J19)/2 -> 1 | K19: =('Annotated by thesis author'!K19+'Annotated by ChatGPT'!K19)/2 -> 2 | L19: =('Annotated by thesis author'!L19+'Annotated by ChatGPT'!L19)/2 -> 0 | M19: 0
A20: 578 | B20: DnD: A Cross-Architecture Deep Neural Network Decompiler | C20: Ruoyu Wu, Taegyu Kim, Dave (Jing) Tian, Antonio Bianchi, Dongyan Xu | D20: https://www.usenix.org/system/files/sec22-wu-ruoyu.pdf | E20: 2022 | F20: =('Annotated by thesis author'!F20+'Annotated by ChatGPT'!F20)/2 -> 0 | G20: =('Annotated by thesis author'!G20+'Annotated by ChatGPT'!G20)/2 -> 0 | H20: =('Annotated by thesis author'!H20+'Annotated by ChatGPT'!H20)/2 -> 0 | I20: =('Annotated by thesis author'!I20+'Annotated by ChatGPT'!I20)/2 -> 0 | J20: =('Annotated by thesis author'!J20+'Annotated by ChatGPT'!J20)/2 -> 1 | K20: =('Annotated by thesis author'!K20+'Annotated by ChatGPT'!K20)/2 -> 1 | L20: =('Annotated by thesis author'!L20+'Annotated by ChatGPT'!L20)/2 -> 2 | M20: 0
A21: 268 | B21: Model Orthogonalization: Class Distance Hardening in Neural Networks for Better Security | C21: Guanhong Tao, Yingqi Liu, Guangyu Shen, Qiuling Xu, Shengwei An, Zhuo Zhang, Xiangyu Zhang | D21: https://ieeexplore.ieee.org/document/9833688 | E21: 2022 | F21: =('Annotated by thesis author'!F21+'Annotated by ChatGPT'!F21)/2 -> 0 | G21: =('Annotated by thesis author'!G21+'Annotated by ChatGPT'!G21)/2 -> 0 | H21: =('Annotated by thesis author'!H21+'Annotated by ChatGPT'!H21)/2 -> 0 | I21: =('Annotated by thesis author'!I21+'Annotated by ChatGPT'!I21)/2 -> 1 | J21: =('Annotated by thesis author'!J21+'Annotated by ChatGPT'!J21)/2 -> 2 | K21: =('Annotated by thesis author'!K21+'Annotated by ChatGPT'!K21)/2 -> 1 | L21: =('Annotated by thesis author'!L21+'Annotated by ChatGPT'!L21)/2 -> 0 | M21: 0
A22: 655 | B22: To Err.Is Human: Characterizing the Threat of Unintended URLs in Social Media | C22: Beliz Kaleli Boston, Brian Kondracki, Manuel Egele, Nick Nikiforakis, Gianluca Stringhini | D22: https://www.ndss-symposium.org/wp-content/uploads/ndss2021_3A-4_24322_paper.pdf | E22: 2021 | F22: =('Annotated by thesis author'!F22+'Annotated by ChatGPT'!F22)/2 -> 2 | G22: =('Annotated by thesis author'!G22+'Annotated by ChatGPT'!G22)/2 -> 0 | H22: =('Annotated by thesis author'!H22+'Annotated by ChatGPT'!H22)/2 -> 0 | I22: =('Annotated by thesis author'!I22+'Annotated by ChatGPT'!I22)/2 -> 1 | J22: =('Annotated by thesis author'!J22+'Annotated by ChatGPT'!J22)/2 -> 1 | K22: =('Annotated by thesis author'!K22+'Annotated by ChatGPT'!K22)/2 -> 2 | L22: =('Annotated by thesis author'!L22+'Annotated by ChatGPT'!L22)/2 -> 0 | M22: 0
A23: 556 | B23: Khaleesi: Breaker of Advertising and Tracking Request Chains | C23: Umar Iqbal, Charlie Wolfe, Charles Nguyen, Steven Englehardt, Zubair Shafiq | D23: https://www.usenix.org/system/files/sec22-iqbal.pdf | E23: 2022 | F23: =('Annotated by thesis author'!F23+'Annotated by ChatGPT'!F23)/2 -> 2 | G23: =('Annotated by thesis author'!G23+'Annotated by ChatGPT'!G23)/2 -> 1 | H23: =('Annotated by thesis author'!H23+'Annotated by ChatGPT'!H23)/2 -> 0 | I23: =('Annotated by thesis author'!I23+'Annotated by ChatGPT'!I23)/2 -> 1 | J23: =('Annotated by thesis author'!J23+'Annotated by ChatGPT'!J23)/2 -> 2 | K23: =('Annotated by thesis author'!K23+'Annotated by ChatGPT'!K23)/2 -> 2 | L23: =('Annotated by thesis author'!L23+'Annotated by ChatGPT'!L23)/2 -> 1 | M23: 1
A24: 317 | B24: Practical Evasion of a Learning-Based Classifier: A Case Study | C24: Nedim Srndic and Pavel Laskov | D24: https://ieeexplore.ieee.org/stamp/stamp.jsp?tp=&arnumber=6956565 | E24: 2014 | F24: =('Annotated by thesis author'!F24+'Annotated by ChatGPT'!F24)/2 -> 1 | G24: =('Annotated by thesis author'!G24+'Annotated by ChatGPT'!G24)/2 -> 0 | H24: =('Annotated by thesis author'!H24+'Annotated by ChatGPT'!H24)/2 -> 0 | I24: =('Annotated by thesis author'!I24+'Annotated by ChatGPT'!I24)/2 -> 1 | J24: =('Annotated by thesis author'!J24+'Annotated by ChatGPT'!J24)/2 -> 1 | K24: =('Annotated by thesis author'!K24+'Annotated by ChatGPT'!K24)/2 -> 1 | L24: =('Annotated by thesis author'!L24+'Annotated by ChatGPT'!L24)/2 -> 2 | M24: 0
A25: 98 | B25: Adversarial Attacks Against Automatic Speech_x000D_ Recognition Systems via Psychoacoustic Hiding | C25: Lea Schonherr, Katharina Kohls, Steffen Zeiler, Thorsten Holz, and Dorothea Kolossa | D25: https://arxiv.org/pdf/1808.05665.pdf | E25: 2019 | F25: =('Annotated by thesis author'!F25+'Annotated by ChatGPT'!F25)/2 -> 2 | G25: =('Annotated by thesis author'!G25+'Annotated by ChatGPT'!G25)/2 -> 0 | H25: =('Annotated by thesis author'!H25+'Annotated by ChatGPT'!H25)/2 -> 0 | I25: =('Annotated by thesis author'!I25+'Annotated by ChatGPT'!I25)/2 -> 1 | J25: =('Annotated by thesis author'!J25+'Annotated by ChatGPT'!J25)/2 -> 1 | K25: =('Annotated by thesis author'!K25+'Annotated by ChatGPT'!K25)/2 -> 2 | L25: =('Annotated by thesis author'!L25+'Annotated by ChatGPT'!L25)/2 -> 0 | M25: 0
A26: 422 | B26: Devilâ€™s Whisper: A General Approach for Physical Adversarial Attacks against Commercial Black-box Speech Recognition Devices | C26: Yuxuan Chen; Xuejing Yuan; Jiangshan Zhang; Yue Zhao; Shengzhi Zhang; Kai Chen; XiaoFeng Wang | D26: https://www.usenix.org/system/files/sec20-chen-yuxuan.pdf | E26: 2020 | F26: =('Annotated by thesis author'!F26+'Annotated by ChatGPT'!F26)/2 -> 3 | G26: =('Annotated by thesis author'!G26+'Annotated by ChatGPT'!G26)/2 -> 2 | H26: =('Annotated by thesis author'!H26+'Annotated by ChatGPT'!H26)/2 -> 1 | I26: =('Annotated by thesis author'!I26+'Annotated by ChatGPT'!I26)/2 -> 1 | J26: =('Annotated by thesis author'!J26+'Annotated by ChatGPT'!J26)/2 -> 1 | K26: 1 | L26: =('Annotated by thesis author'!L26+'Annotated by ChatGPT'!L26)/2 -> 2 | M26: 0
A27: 562 | B27: Transferring Adversarial Robustness Through Robust Representation Matching | C27: Pratik Vaishnavi, Kevin Eykholt, Amir Rahmati | D27: https://www.usenix.org/system/files/sec22-vaishnavi.pdf | E27: 2022 | F27: =('Annotated by thesis author'!F27+'Annotated by ChatGPT'!F27)/2 -> 2 | G27: =('Annotated by thesis author'!G27+'Annotated by ChatGPT'!G27)/2 -> 0 | H27: =('Annotated by thesis author'!H27+'Annotated by ChatGPT'!H27)/2 -> 1 | I27: =('Annotated by thesis author'!I27+'Annotated by ChatGPT'!I27)/2 -> 2 | J27: =('Annotated by thesis author'!J27+'Annotated by ChatGPT'!J27)/2 -> 2 | K27: =('Annotated by thesis author'!K27+'Annotated by ChatGPT'!K27)/2 -> 2 | L27: =('Annotated by thesis author'!L27+'Annotated by ChatGPT'!L27)/2 -> 1 | M27: 0
A28: 669 | B28: FlowLens: Enabling Efficient Flow Classification for ML-based Network Security Applications | C28: Diogo Barradas, Nuno Santos, Lu ÌÄ±s Rodrigues, Salvatore Signorello, Fernando M. V. Ramos, Andre Ì Madeira | D28: https://www.ndss-symposium.org/wp-content/uploads/ndss2021_7C-2_24067_paper.pdf | E28: 2021 | F28: =('Annotated by thesis author'!F28+'Annotated by ChatGPT'!F28)/2 -> 0 | G28: =('Annotated by thesis author'!G28+'Annotated by ChatGPT'!G28)/2 -> 0 | H28: =('Annotated by thesis author'!H28+'Annotated by ChatGPT'!H28)/2 -> 0 | I28: =('Annotated by thesis author'!I28+'Annotated by ChatGPT'!I28)/2 -> 1 | J28: =('Annotated by thesis author'!J28+'Annotated by ChatGPT'!J28)/2 -> 1 | K28: =('Annotated by thesis author'!K28+'Annotated by ChatGPT'!K28)/2 -> 1 | L28: =('Annotated by thesis author'!L28+'Annotated by ChatGPT'!L28)/2 -> 0 | M28: 0
A29: 70 | B29: Learning to Fuzz from Symbolic Execution with Application to Smart Contracts | C29: Jingxuan He, Mislav BalunoviÆ’Ã¡, Nodar Ambroladze, Petar Tsankov, Martin Vechev | D29: https://dl.acm.org/doi/pdf/10.1145/3319535.3363230 | E29: 2019 | F29: =('Annotated by thesis author'!F29+'Annotated by ChatGPT'!F29)/2 -> 3 | G29: =('Annotated by thesis author'!G29+'Annotated by ChatGPT'!G29)/2 -> 0 | H29: =('Annotated by thesis author'!H29+'Annotated by ChatGPT'!H29)/2 -> 1 | I29: =('Annotated by thesis author'!I29+'Annotated by ChatGPT'!I29)/2 -> 2 | J29: =('Annotated by thesis author'!J29+'Annotated by ChatGPT'!J29)/2 -> 2 | K29: =('Annotated by thesis author'!K29+'Annotated by ChatGPT'!K29)/2 -> 1 | L29: =('Annotated by thesis author'!L29+'Annotated by ChatGPT'!L29)/2 -> 2 | M29: 0
A30: 151 | B30: When Malware is Packinâ€™ Heat;_x000D_ Limits of Machine Learning Classifiers Based on_x000D_ Static Analysis Features | C30: Hojjat Aghakhani, Fabio Gritti, Francesco Mecca, Martina Lindorfer, Stefano Ortolani, Davide Balzarotti, Giovanni Vigna, and Christopher Kruegel | D30: https://www.ndss-symposium.org/wp-content/uploads/2020/02/24310-paper.pdf | E30: 2020 | F30: =('Annotated by thesis author'!F30+'Annotated by ChatGPT'!F30)/2 -> 3 | G30: =('Annotated by thesis author'!G30+'Annotated by ChatGPT'!G30)/2 -> 2 | H30: =('Annotated by thesis author'!H30+'Annotated by ChatGPT'!H30)/2 -> 1 | I30: =('Annotated by thesis author'!I30+'Annotated by ChatGPT'!I30)/2 -> 2 | J30: =('Annotated by thesis author'!J30+'Annotated by ChatGPT'!J30)/2 -> 2 | K30: =('Annotated by thesis author'!K30+'Annotated by ChatGPT'!K30)/2 -> 2 | L30: =('Annotated by thesis author'!L30+'Annotated by ChatGPT'!L30)/2 -> 2 | M30: 0
A31: 571 | B31: Blacklight: Scalable Defense for Neural Networks against Query-Based Black-Box Attacks | C31: Huiying Li, Shawn Shan, Emily Wenger, Jiayun Zhang, Haitao Zheng, Ben Y. Zhao | D31: https://www.usenix.org/system/files/sec22-li-huiying.pdf | E31: 2022 | F31: =('Annotated by thesis author'!F31+'Annotated by ChatGPT'!F31)/2 -> 3 | G31: =('Annotated by thesis author'!G31+'Annotated by ChatGPT'!G31)/2 -> 0 | H31: =('Annotated by thesis author'!H31+'Annotated by ChatGPT'!H31)/2 -> 0 | I31: =('Annotated by thesis author'!I31+'Annotated by ChatGPT'!I31)/2 -> 2 | J31: =('Annotated by thesis author'!J31+'Annotated by ChatGPT'!J31)/2 -> 1 | K31: =('Annotated by thesis author'!K31+'Annotated by ChatGPT'!K31)/2 -> 2 | L31: =('Annotated by thesis author'!L31+'Annotated by ChatGPT'!L31)/2 -> 2 | M31: 1
A32: 430 | B32: Sunlight: Fine-grained Targeting Detection at Scale with Statistical Confidence | C32: Mathias LÃ©cuyer, Riley Spahn, Yannis Spiliopolous, Augustin Chaintreau, Roxana Geambasu, Daniel J. Hsu | D32: https://doi.org/10.1145/2810103.2813614 | E32: 2015 | F32: =('Annotated by thesis author'!F32+'Annotated by ChatGPT'!F32)/2 -> 3 | G32: =('Annotated by thesis author'!G32+'Annotated by ChatGPT'!G32)/2 -> 1 | H32: =('Annotated by thesis author'!H32+'Annotated by ChatGPT'!H32)/2 -> 0 | I32: =('Annotated by thesis author'!I32+'Annotated by ChatGPT'!I32)/2 -> 1 | J32: =('Annotated by thesis author'!J32+'Annotated by ChatGPT'!J32)/2 -> 1 | K32: =('Annotated by thesis author'!K32+'Annotated by ChatGPT'!K32)/2 -> 1 | L32: =('Annotated by thesis author'!L32+'Annotated by ChatGPT'!L32)/2 -> 1 | M32: 0
A33: 244 | B33: Towards Evaluating the Robustness of Neural Networks | C33: Nicholas Carlini, David Wagner | D33: https://www.ieee-security.org/TC/SP2017/papers/518.pdf | E33: 2017 | F33: =('Annotated by thesis author'!F33+'Annotated by ChatGPT'!F33)/2 -> 3 | G33: =('Annotated by thesis author'!G33+'Annotated by ChatGPT'!G33)/2 -> 0 | H33: =('Annotated by thesis author'!H33+'Annotated by ChatGPT'!H33)/2 -> 0 | I33: =('Annotated by thesis author'!I33+'Annotated by ChatGPT'!I33)/2 -> 2 | J33: =('Annotated by thesis author'!J33+'Annotated by ChatGPT'!J33)/2 -> 2 | K33: =('Annotated by thesis author'!K33+'Annotated by ChatGPT'!K33)/2 -> 2 | L33: =('Annotated by thesis author'!L33+'Annotated by ChatGPT'!L33)/2 -> 1 | M33: 1
A34: 455 | B34: BadEncoder: Backdoor Attacks to Pre-trained Encoders in Self-Supervised Learning | C34: Jinyuan Jia, Yupei Liu, Neil Zhenqiang Gong | D34: https://doi.org/10.1109/SP46214.2022.9833644 | E34: 2022 | F34: =('Annotated by thesis author'!F34+'Annotated by ChatGPT'!F34)/2 -> 3 | G34: =('Annotated by thesis author'!G34+'Annotated by ChatGPT'!G34)/2 -> 0 | H34: =('Annotated by thesis author'!H34+'Annotated by ChatGPT'!H34)/2 -> 0 | I34: =('Annotated by thesis author'!I34+'Annotated by ChatGPT'!I34)/2 -> 2 | J34: =('Annotated by thesis author'!J34+'Annotated by ChatGPT'!J34)/2 -> 2 | K34: =('Annotated by thesis author'!K34+'Annotated by ChatGPT'!K34)/2 -> 2 | L34: =('Annotated by thesis author'!L34+'Annotated by ChatGPT'!L34)/2 -> 2 | M34: 0
A35: 671 | B35: XDA: Accurate, Robust Disassembly with Transfer Learning | C35: Kexin Pei, Jonas Guan, David Williams-King, Junfeng Yang, Suman Jana | D35: https://www.ndss-symposium.org/wp-content/uploads/ndss2021_1B-3_23112_paper.pdf | E35: 2021 | F35: =('Annotated by thesis author'!F35+'Annotated by ChatGPT'!F35)/2 -> 0 | G35: =('Annotated by thesis author'!G35+'Annotated by ChatGPT'!G35)/2 -> 2 | H35: =('Annotated by thesis author'!H35+'Annotated by ChatGPT'!H35)/2 -> 1 | I35: =('Annotated by thesis author'!I35+'Annotated by ChatGPT'!I35)/2 -> 2 | J35: =('Annotated by thesis author'!J35+'Annotated by ChatGPT'!J35)/2 -> 2 | K35: =('Annotated by thesis author'!K35+'Annotated by ChatGPT'!K35)/2 -> 2 | L35: =('Annotated by thesis author'!L35+'Annotated by ChatGPT'!L35)/2 -> 2 | M35: 1
A36: 483 | B36: Reconstructing Training Data with Informed Adversaries | C36: Borja Balle, Giovanni Cherubin, Jamie Hayes | D36: https://doi.org/10.1109/SP46214.2022.9833677 | E36: 2022 | F36: =('Annotated by thesis author'!F36+'Annotated by ChatGPT'!F36)/2 -> 3 | G36: =('Annotated by thesis author'!G36+'Annotated by ChatGPT'!G36)/2 -> 0 | H36: =('Annotated by thesis author'!H36+'Annotated by ChatGPT'!H36)/2 -> 0 | I36: =('Annotated by thesis author'!I36+'Annotated by ChatGPT'!I36)/2 -> 2 | J36: =('Annotated by thesis author'!J36+'Annotated by ChatGPT'!J36)/2 -> 2 | K36: =('Annotated by thesis author'!K36+'Annotated by ChatGPT'!K36)/2 -> 2 | L36: =('Annotated by thesis author'!L36+'Annotated by ChatGPT'!L36)/2 -> 2 | M36: 1
A37: 496 | B37: Exposing the Rat in the Tunnel: Using Traffic Analysis for Tor-based Malware Detection | C37: Priyanka Dodia, Mashael AlSabah, Omar Alrawi, Tao Wang | D37: https://dl.acm.org/doi/pdf/10.1145/3548606.3560604 | E37: 2022 | F37: =('Annotated by thesis author'!F37+'Annotated by ChatGPT'!F37)/2 -> 3 | G37: =('Annotated by thesis author'!G37+'Annotated by ChatGPT'!G37)/2 -> 1 | H37: =('Annotated by thesis author'!H37+'Annotated by ChatGPT'!H37)/2 -> 1 | I37: =('Annotated by thesis author'!I37+'Annotated by ChatGPT'!I37)/2 -> 1 | J37: =('Annotated by thesis author'!J37+'Annotated by ChatGPT'!J37)/2 -> 2 | K37: =('Annotated by thesis author'!K37+'Annotated by ChatGPT'!K37)/2 -> 2 | L37: =('Annotated by thesis author'!L37+'Annotated by ChatGPT'!L37)/2 -> 1 | M37: 0
A38: 307 | B38: Gyrophone: Recognizing Speech From Gyroscope Signals | C38: Yan Michalevsky; Dan Boneh; Gabi Nakibly | D38: https://www.usenix.org/system/files/conference/usenixsecurity14/sec14-paper-michalevsky.pdf | E38: 2014 | F38: =('Annotated by thesis author'!F38+'Annotated by ChatGPT'!F38)/2 -> 3 | G38: =('Annotated by thesis author'!G38+'Annotated by ChatGPT'!G38)/2 -> 2 | H38: =('Annotated by thesis author'!H38+'Annotated by ChatGPT'!H38)/2 -> 0 | I38: =('Annotated by thesis author'!I38+'Annotated by ChatGPT'!I38)/2 -> 1 | J38: =('Annotated by thesis author'!J38+'Annotated by ChatGPT'!J38)/2 -> 1 | K38: =('Annotated by thesis author'!K38+'Annotated by ChatGPT'!K38)/2 -> 1 | L38: =('Annotated by thesis author'!L38+'Annotated by ChatGPT'!L38)/2 -> 1 | M38: 0
... A42: 373 | B42: Deep Fingerprinting: Undermining Website Fingerprinting Defenses with Deep Learning | C42: Payap Sirinam; Mohsen Imani; Marc Juarez; Matthew Wright | D42: https://dl.acm.org/doi/pdf/10.1145/3243734.3243768 | E42: 2018 | F42: =('Annotated by thesis author'!F42+'Annotated by ChatGPT'!F42)/2 -> 2 | G42: =('Annotated by thesis author'!G42+'Annotated by ChatGPT'!G42)/2 -> 2 | H42: =('Annotated by thesis author'!H42+'Annotated by ChatGPT'!H42)/2 -> 0 | I42: =('Annotated by thesis author'!I42+'Annotated by ChatGPT'!I42)/2 -> 2 | J42: =('Annotated by thesis author'!J42+'Annotated by ChatGPT'!J42)/2 -> 2 | K42: =('Annotated by thesis author'!K42+'Annotated by ChatGPT'!K42)/2 -> 1 | L42: =('Annotated by thesis author'!L42+'Annotated by ChatGPT'!L42)/2 -> 2 | M42: 0
A43: 650 | B43: Dirty Road Can Attack: Security of Deep Learning based Automated Lane Centering under Physical-World Attack | C43: Takami Sato, Junjie Shen, and Ningfei Wang, Yunhan Jia, Xue Lin, Qi Alfred Chen | D43: https://www.usenix.org/system/files/sec21-sato.pdf | E43: 2021 | F43: 2 | G43: =('Annotated by thesis author'!G43+'Annotated by ChatGPT'!G43)/2 -> 1 | H43: =('Annotated by thesis author'!H43+'Annotated by ChatGPT'!H43)/2 -> 1 | I43: =('Annotated by thesis author'!I43+'Annotated by ChatGPT'!I43)/2 -> 2 | J43: =('Annotated by thesis author'!J43+'Annotated by ChatGPT'!J43)/2 -> 2 | K43: =('Annotated by thesis author'!K43+'Annotated by ChatGPT'!K43)/2 -> 2 | L43: =('Annotated by thesis author'!L43+'Annotated by ChatGPT'!L43)/2 -> 2 | M43: 1
...
